Workbook
Name _: #REF!
Name _: #REF!
Name _: #REF!
Name _: #REF!
Name _: #REF!
Name ___GR2: #REF!
Name ___GR2: #REF!
Name ___GR2: #REF!
Name ___GR2: #REF!
Name ___GR2: #REF!
Name ___GR2: #REF!
Name ___GR2: #REF!
Name ___GR2: #REF!
Name ___GR2: #REF!
Name ___GR2: #REF!
Name ___GR2: #REF!
Name ___GR2: #REF!
Name __age1: #REF!
Name __age1: #REF!
Name __age1: #REF!
Name __age1: #REF!
Name __age1: #REF!
Name __age1: #REF!
Name __age1: #REF!
Name __age1: #REF!
Name __age10: #REF!
Name __age10: #REF!
Name __age10: #REF!
Name __age10: #REF!
Name __age10: #REF!
Name __age12: #REF!
Name __age12: #REF!
Name __age12: #REF!
Name __age12: #REF!
Name __age12: #REF!
Name __age15: #REF!
Name __age15: #REF!
Name __age15: #REF!
Name __age20: #REF!
Name __age20: #REF!
Name __age20: #REF!
Name __age25: #REF!
Name __age25: #REF!
Name __age25: #REF!
Name __age30: #REF!
Name __age30: #REF!
Name __age30: #REF!
Name __age35: #REF!
Name __age35: #REF!
Name __age35: #REF!
Name __age5: #REF!
Name __age5: #REF!
Name __age5: #REF!
Name __age7: #REF!
Name __age7: #REF!
Name __age7: #REF!
Name __CHF2001: #REF!
Name __CHF2001: #REF!
Name __CHF2001: #REF!
Name __DEP1: #REF!

Sheet WACC_SECTOR GREEN ENERGY (2)
B1: DATOS | C1: FUENTE | G1: VALORES | H1: OBSERVACIÓN
B2: BETA DESAPALANCADA DE LA IND. | C2: http://pages.stern.nyu.edu/~adamodar/New_Home_Page/datafile/Betas.html | G2: =+'Betas 2025'!I117 -> 0.9791328 | H2: 2023
B3: D/E = APALANCAMIENTO | C3: http://pages.stern.nyu.edu/~adamodar/New_Home_Page/datafile/Betas.html | G3: =+'Betas 2025'!D117 -> 0.1792 | H3: 2023
B4: TASA LIBRE DE RIESGO | C4: Tbon 10 años (últimos 20 años) | G4: #REF! | H4: 44951
B5: PREMIO POR RIESGO | C5: http://pages.stern.nyu.edu/~adamodar/New_Home_Page/datafile/ctryprem.html | G5: #REF! | H5: 2023
B6: RIESGO PAÍS | C6: https://estadisticas.bcrp.gob.pe/estadisticas/series/diarias/resultados/PD04713XD/html | G6: 0.0363 | H6: 44944
B8: BETA DESAPALANCADA DE LA IND. | C8: Bu | D8: =+G2 -> 0.9791328
B9: D/E = APALANCAMIENTO | C9: D/P | D9: =+G3 -> 0.1792
B10: TASA DE IMPUESTOS | C10: t | D10: 0.3
B11: BETA APALANCADA DE LA EMPRESA | C11: BL | D11: =+D8*(1+(1-D10)*D9) -> 1.1019552
B14: CÁLCULO DE TASA DE DESCUENTO (ke) | F14: CÁLCULO DE TASA DE DESCUENTO (WACC)
B16: fórmula a utilizar (1) | F16: fórmula a utilizar (2)
B17: Ke= Rf + (Rm-Rf)B + Rp + SCP
B19: Ke= | C19: =C22+(C24)*C23+C25+C26 -> #VALUE!
F21: Kd= | G21: 0.1141
B22: TASA LIBRE DE RIESGO (RF) | C22: =+G4 -> #REF! | F22: ke= | G22: =C19 -> #VALUE!
B23: BETA DE LA EMPRESA (B) | C23: =+D11 -> 1.1019552 | F23: T= | G23: 0.3
B24: PREMIO POR RIESGO ( RM - RF ) | C24: =+G5 -> #REF! | F24: D= | G24: =+H30/(H31+H30) -> #VALUE!
B25: RIESGO PAÍS (URUGUAY) (RP) | C25: =+G6 -> 0.0363 | F25: C= | G25: =+H31/(H30+H31) -> #VALUE!
B26: PRIMA TAMAÑO EMPRESA (SCP) | C26: 0.01 | F26: wacc= | G26: =((G25)*(G22)+((G24)*(1-G23)*(G21))) -> #VALUE!
F28: Wacc= | G28: =+G26 -> #VALUE!
G30: DLP | H30: #REF!
G31: C | H31: #REF!
G32: % DLP | H32: #REF!
G33: % C | H33: #REF!

Sheet RESUMEN
A1: Valoracion Negocio En Marcha Grupo OVANDO
A2: CONCEPTO | B2: Valor | C2: Comentario
A4: WACC | B4: =WACC!K26 -> 0.15953943 | C4: Considero adecuada la WACC, se deefinió un nivel de riesgo medio y se tomaron los datos de damodaran para modelar, se sensibilizó con la falta de deuda a largo plazo
A5: Valor Neto Contable | B5: ='VALOR NETO CONTABLE'!C23 -> 0 | C5: Tomado de cruce contable
A6: EBITDA 2025 | B6: ='1. Datos'!J30 -> 0 | C6: Tomado a cierre del 25
A7: Valor compañía por flujos | B7: ='4.Resumen-Escenario'!AP36 -> #DIV/0! | C7: No es muy alta porque la compañía venia presentamndo flujos bajos, hasta el 2025 el EBITDA es relativamente bueno, tuvo un crecimiento exponencial de más del 70% en comparación con los años anteriores
A8: Veces EBITDA | B8: =B7/B6 -> #DIV/0! | C8: Si se compara con la media estamos sobre la cota baja, pero dado el tamaño de la compañía y el comportamiento de valor considero adecuado el valor
A11: Multiplos de EBITDA para venta | B11: =(12.2+6.5)/2 -> 9.35 | C11: Media del rango definido por segmento de negocio en Atlas KPMG | D11: https://atlas.kpmg.com/de/en/deal-advisory-services/cost-of-capital-and-multiples/industry-specific-multiples?utm_source=chatgpt.com
A12: EBITDA ULTIMO AÑO | B12: =B6 -> 0
A13: Valor por EBITDA | B13: =B11*B6 -> 0 | C13: Se toma como techo
A14: PROYECCIONES
F27: https://atlas.kpmg.com/de/en/deal-advisory-services/cost-of-capital-and-multiples/industry-specific-multiples?utm_source=chatgpt.com

Sheet WACC
B1: DATOS | C1: FUENTE | G1: VALORES | H1: OBSERVACIÓN
B2: BETA DESAPALANCADA DE LA IND. | C2: http://pages.stern.nyu.edu/~adamodar/New_Home_Page/datafile/Betas.html | G2: ='Betas 2025'!I117 -> 0.9791328 | H2: 2025
B3: D/E = APALANCAMIENTO | C3: http://pages.stern.nyu.edu/~adamodar/New_Home_Page/datafile/Betas.html | G3: ='Betas 2025'!D117 -> 0.1792 | H3: 2025
B4: TASA LIBRE DE RIESGO | C4: Tbon 10 años (últimos 20 años) | G4: 0.0417 | H4: =TODAY() -> 46072
B5: PREMIO POR RIESGO | C5: http://pages.stern.nyu.edu/~adamodar/New_Home_Page/datafile/ctryprem.html | G5: 0.0687 | H5: 2025
B6: RIESGO PAÍS | C6: https://estadisticas.bcrp.gob.pe/estadisticas/series/diarias/resultados/PD04713XD/html | G6: 0.0257 | H6: =TODAY() -> 46072
B8: BETA DESAPALANCADA DE LA IND. | C8: Bu | D8: =+G2 -> 0.9791328 | I8: FUENTE | J8: PORCENTAJE
B9: D/E = APALANCAMIENTO | C9: D/P | D9: =G3 -> 0.1792 | I9: Barregio, 2025 | J9: 0.25
B10: TASA DE IMPUESTOS | C10: t | D10: 0.3 | I10: Banorte, 2025 | J10: 0.2115
B11: BETA APALANCADA DE LA EMPRESA | C11: BL | D11: =+D8*(1+(1-D10)*D9) -> 1.1019552 | I11: HSBC, 2025 | J11: 0.206
J13: =AVERAGE(J9:J12) -> 0.2225
B14: CÁLCULO DE TASA DE DESCUENTO (ke) | F14: CÁLCULO DE TASA DE DESCUENTO (WACC)
K15: SECTOR
B16: fórmula a utilizar (1) | F16: fórmula a utilizar (2) | J16: fórmula a utilizar (2)
B17: Ke= Rf + (Rm-Rf)B + Rp + SCP
B19: Ke= | C19: =C22+(C24)*C23+C25+C26 -> 0.16310432
F21: Kd= | G21: =J13 -> 0.2225 | J21: Kd= | K21: =+J13 -> 0.2225
B22: TASA LIBRE DE RIESGO (RF) | C22: =+G4 -> 0.0417 | F22: ke= | G22: =C19 -> 0.16310432 | J22: ke= | K22: =+C19 -> 0.16310432
B23: BETA DE LA EMPRESA (B) | C23: =+D11 -> 1.1019552 | F23: T= | G23: 0.3 | J23: T= | K23: 0.3
B24: PREMIO POR RIESGO ( RM - RF ) | C24: =+G5 -> 0.0687 | F24: D= | G24: =+I28 -> #DIV/0! | J24: D= | K24: =I30 -> 0.48473411
B25: RIESGO PAÍS ( (RP) | C25: =+G6 -> 0.0257 | F25: C= | G25: =+I29 -> #DIV/0! | J25: C= | K25: =I31 -> 0.51526589
B26: PRIMA TAMAÑO EMPRESA (SCP) | C26: 0.02 | F26: wacc= | G26: =((G25)*(G22)+((G24)*(1-G23)*(G21))) -> #DIV/0! | J26: wacc= | K26: =((K25)*(K22)+((K24)*(1-K23)*(K21))) -> 0.15953943
F28: Wacc= | G28: =+G26 -> #DIV/0! | I28: =+H30/H32 -> #DIV/0!
I29: =+H31/H32 -> #DIV/0!
G30: DLP | H30: =+'1. Datos'!J119 -> 0 | I30: =+'Estructura de deuda'!J49 -> 0.48473411
G31: C | H31: =+'1. Datos'!J125 -> 0 | I31: =+'Estructura de deuda'!E49 -> 0.51526589
F32: SECTOR | G32: TOTAL | H32: =SUM(H30+H31) -> 0

Sheet Betas 2025
A1: Date updated: | B1: 45662 | H1: YouTube Video explaining estimation choices and process. | I1: Notes
A2: Created by: | B2: Aswath Damodaran, adamodar@stern.nyu.edu | I2: if you are looking for a pure-play beta, i.e., a beta for a business, the unlevered beta corrected for cash is your best bet. Since even sector betas can move over time, I have also reported the average of the this sector beta across time in the last column. This number, for obvious reasons, is less likely to be volatile over time.
A3: What is this data? | B3: Beta, Unlevered beta and other risk measures | F3: US companies
A4: Home Page: | B4: http://www.damodaran.com
A5: Data website: | B5: https://pages.stern.nyu.edu/~adamodar/New_Home_Page/datafile/Betas.html
A6: Companies in each industry: | B6: https://pages.stern.nyu.edu/~adamodar/pc/datasets/indname.xls
A7: Variable definitions: | B7: https://pages.stern.nyu.edu/~adamodar/New_Home_Page/datafile/variable.htm
A8: Do you want to use marginal or effective tax rates in unlevering betas? | F8: Marginal
A9: If marginal tax rate, enter the marginal tax rate to use | F9: 0.25 | L9: Unlevered beta corrected for cash - Over time
A10: Industry name | B10: Number of firms | C10: Beta | D10: D/E Ratio | E10: Effective Tax rate | F10: Unlevered beta | G10: Cash/Firm value | H10: Unlevered beta corrected for cash | I10: HiLo Risk | J10: Standard deviation of equity | K10: Standard deviation in operating income (last 10 years) | L10: 2019 | M10: 2020 | N10: 2021 | O10: 2022 | P10: Average (2019-23)
A11: Advertising | B11: 54 | C11: 1.34 | D11: 0.262 | E11: 0.0767 | F11: 1.12 | G11: 0.0656 | H11: 1.2 | I11: 0.6098 | J11: 0.6719 | K11: 0.121 | L11: 0.93 | M11: 0.77 | N11: 1.1 | O11: 1.35 | P11: 1.07
A12: Aerospace/Defense | B12: 67 | C12: 0.9 | D12: 0.2279 | E12: 0.1102 | F12: 0.77 | G12: 0.0387 | H12: 0.8 | I12: 0.4341 | J12: 0.4274 | K12: 0.2392 | L12: 1.08 | M12: 0.91 | N12: 1.11 | O12: 1.23 | P12: 1.05
A13: Air Transport | B13: 24 | C13: 1.24 | D13: 1.0683 | E13: 0.1015 | F13: 0.69 | G13: 0.1028 | H13: 0.76 | I13: 0.5255 | J13: 0.6527 | K13: 2.0402 | L13: 0.84 | M13: 0.91 | N13: 0.91 | O13: 0.69 | P13: 0.8
A14: Apparel | B14: 37 | C14: 0.99 | D14: 0.4589 | E14: 0.0808 | F14: 0.74 | G14: 0.1086 | H14: 0.83 | I14: 0.4841 | J14: 0.5093 | K14: 0.2449 | L14: 0.83 | M14: 0.94 | N14: 1.1 | O14: 1.02 | P14: 0.96
A15: Auto & Truck | B15: 34 | C15: 1.62 | D15: 0.224 | E15: 0.0211 | F15: 1.39 | G15: 0.0351 | H15: 1.43 | I15: 0.6646 | J15: 0.7759 | K15: 0.4693 | L15: 0.53 | M15: 1.05 | N15: 1.02 | O15: 1.23 | P15: 1.03
A16: Auto Parts | B16: 33 | C16: 1.23 | D16: 0.4783 | E16: 0.1277 | F16: 0.91 | G16: 0.0861 | H16: 0.99 | I16: 0.3843 | J16: 0.5262 | K16: 0.2056 | L16: 0.95 | M16: 1.09 | N16: 1.21 | O16: 1.2 | P16: 1.11
A17: Bank (Money Center) | B17: 15 | C17: 0.88 | D17: 1.8319 | E17: 0.181 | F17: 0.37 | G17: 0.2977 | H17: 0.53 | I17: 0.2337 | J17: 0.3047 | K17: NA | L17: 0.56 | M17: 0.59 | N17: 1.03 | O17: 0.74 | P17: 0.71
A18: Banks (Regional) | B18: 591 | C18: 0.52 | D18: 0.6032 | E18: 0.1684 | F18: 0.36 | G18: 0.2475 | H18: 0.48 | I18: 0.2078 | J18: 0.2996 | K18: 2.6519 | L18: 0.43 | M18: 0.6 | N18: 0.84 | O18: 0.41 | P18: 0.52
A19: Beverage (Alcoholic) | B19: 18 | C19: 0.61 | D19: 0.3047 | E19: 0.0828 | F19: 0.5 | G19: 0.0186 | H19: 0.51 | I19: 0.5509 | J19: 0.6308 | K19: 0.2167 | L19: 0.92 | M19: 0.67 | N19: 0.72 | O19: 0.88 | P19: 0.83
A20: Beverage (Soft) | B20: 29 | C20: 0.57 | D20: 0.1973 | E20: 0.0694 | F20: 0.5 | G20: 0.0357 | H20: 0.51 | I20: 0.6427 | J20: 0.4767 | K20: 0.1538 | L20: 1.09 | M20: 0.71 | N20: 1.12 | O20: 1.2 | P20: 0.96
A21: Broadcasting | B21: 22 | C21: 0.92 | D21: 1.4956 | E21: 0.1074 | F21: 0.43 | G21: 0.0947 | H21: 0.48 | I21: 0.539 | J21: 0.526 | K21: 0.2823 | L21: 0.73 | M21: 0.65 | N21: 0.81 | O21: 0.7 | P21: 0.68
A22: Brokerage & Investment Banking | B22: 30 | C22: 0.95 | D22: 1.8659 | E22: 0.1442 | F22: 0.4 | G22: 0.1559 | H22: 0.47 | I22: 0.399 | J22: 0.4049 | K22: 0.5736 | L22: 0.57 | M22: 0.57 | N22: 0.67 | O22: 0.69 | P22: 0.61
A23: Building Materials | B23: 39 | C23: 1.36 | D23: 0.1897 | E23: 0.1911 | F23: 1.19 | G23: 0.0357 | H23: 1.23 | I23: 0.3033 | J23: 0.3475 | K23: 0.4633 | L23: 1.02 | M23: 0.97 | N23: 1.09 | O23: 1.1 | P23: 1.08
A24: Business & Consumer Services | B24: 152 | C24: 1 | D24: 0.1678 | E24: 0.1248 | F24: 0.89 | G24: 0.0327 | H24: 0.92 | I24: 0.4832 | J24: 0.4539 | K24: 0.2612 | L24: 0.89 | M24: 0.83 | N24: 0.99 | O24: 1.02 | P24: 0.93
A25: Cable TV | B25: 9 | C25: 0.96 | D25: 1.2635 | E25: 0.1047 | F25: 0.49 | G25: 0.0219 | H25: 0.5 | I25: 0.4196 | J25: 0.4973 | K25: 0.2809 | L25: 0.78 | M25: 0.7 | N25: 0.66 | O25: 0.71 | P25: 0.72
A26: Chemical (Basic) | B26: 31 | C26: 1.15 | D26: 0.5825 | E26: 0.0797 | F26: 0.8 | G26: 0.0716 | H26: 0.86 | I26: 0.549 | J26: 0.5002 | K26: 0.3853 | L26: 0.99 | M26: 0.76 | N26: 0.94 | O26: 0.96 | P26: 0.9
A27: Chemical (Diversified) | B27: 4 | C27: 0.99 | D27: 1.1312 | E27: 0 | F27: 0.54 | G27: 0.0734 | H27: 0.58 | I27: 0.2709 | J27: 0.4697 | K27: 0.3849 | L27: 1.21 | M27: 1.03 | N27: 1.21 | O27: 1.09 | P27: 1.07
A28: Chemical (Specialty) | B28: 60 | C28: 0.92 | D28: 0.2712 | E28: 0.0999 | F28: 0.76 | G28: 0.0358 | H28: 0.79 | I28: 0.4247 | J28: 0.4815 | K28: 0.1852 | L28: 0.96 | M28: 0.82 | N28: 1 | O28: 1.12 | P28: 0.97
A29: Coal & Related Energy | B29: 16 | C29: 1.18 | D29: 0.0947 | E29: 0.0277 | F29: 1.1 | G29: 0.1287 | H29: 1.27 | I29: 0.4805 | J29: 0.5378 | K29: 2.4543 | L29: 1.05 | M29: 0.56 | N29: 0.82 | O29: 1.43 | P29: 1.02
... A106: Total Market (without financial | B106: 4935 | C106: 1.09 | D106: 0.1929 | E106: 0.0675 | F106: 0.95 | G106: 0.0289 | H106: 0.98 | I106: 0.5139 | J106: 0.574 | K106: 0.2578 | L106: 1.01 | M106: 0.86 | N106: 1.04 | O106: 1.12 | P106: 1
G107: =1/G13 -> 9.7276265
G108: =1/G50 -> 14.245014
G110: =1/G75 -> 9.2936803
G112: =1/G54 -> 19.34236
G114: =1/G56 -> 32.051282
A115: BETAS
A116: Industry Name | B116: Number of firms | C116: Beta | D116: D/E Ratio | E116: Effective Tax rate | F116: Unlevered beta | G116: SOURCE | H116: Tasa Impuestos MXN | I116: Beta Apalancada al Sector
A117: Engineering/Construction | B117: 42 | C117: 0.99 | D117: 0.1792 | E117: 0.1471 | F117: 0.87 | G117: US | H117: 0.3 | I117: =+F117*(1+(1-H117)*D117) -> 0.9791328

Sheet MARCA (2)
B1: VALOR DE MARCA | L1: RANGO DE REGALIAS
B2: INGRESOS REALES | L2: MIN | M2: MAX
L3: 0.025 | M3: 0.05 | N3: **Se puede evaluar la parte cualitativa de la marca.
D4: 2018 | E4: 2019 | F4: 2020 | G4: 2021 | H4: 2022** | I4: CAGR | J4: Sector | L4: MEDIA
B5: INGRESOS HISTORICOS PESOS CORRIENTES | D5: =+'1. Datos'!#REF! -> #REF! | E5: =+'1. Datos'!E8 -> 0 | F5: =+'1. Datos'!F8 -> 0 | G5: =+'1. Datos'!G8 -> 0 | H5: =+'1. Datos'!H8 -> 0 | I5: =+(H5/F5)^(1/2)-1 -> #DIV/0! | J5: =+'Expected Growth25'!E67 -> 0.0312 | K5: =+(H5/D5)^(0.25)-1 -> #REF! | L5: =+M3/2 -> 0.025
B6: INCREMENTOS | F6: =+F5/E5-1 -> #DIV/0! | G6: =+G5/F5-1 -> #DIV/0! | H6: =+H5/G5-1 -> #DIV/0!
L8: Tasa de Regalía | M8: Homologación
B9: PROYECCIÓN | C9: PARAMETROS | D9: 0.5 | E9: 1.5 | F9: 2.5 | G9: 3.5 | H9: 4.5 | I9: VT | L9: =+L5 -> 0.025
B10: AÑOS | D10: 2023 | E10: =+D10+1 -> 2024 | F10: =+E10+1 -> 2025 | G10: =+F10+1 -> 2026 | H10: =+G10+1 -> 2027 | I10: =+H10 -> 2027 | L10: Eficiencia Operativa | M10: -0.4
B11: CRECIMIENTO SECTOR | D11: =+'Expected Growth25'!E67 -> 0.0312 | E11: =+D11 -> 0.0312 | F11: =+'Expected Growth25'!F67 -> 0.0413 | G11: =+F11 -> 0.0413 | H11: =+G11 -> 0.0413 | M11: =+L5*(1+M10) -> 0.015
B12: INGRESOS | D12: =+H5*(1+D11) -> 0 | E12: =+D12*(1+E11) -> 0 | F12: =+E12*(1+F11) -> 0 | G12: =+F12*(1+G11) -> 0 | H12: =+G12*(1+H11) -> 0 | I12: =+H12 -> 0
B13: AHORRO EN REGALÍAS | C13: 0.05 | D13: =+D12*$C$13 -> 0 | E13: =+E12*$C$13 -> 0 | F13: =+F12*$C$13 -> 0 | G13: =+G12*$C$13 -> 0 | H13: =+H12*$C$13 -> 0 | I13: =+I12*$C$13 -> 0
B14: GASTO POR MANTENIMIENTO | C14: 0.05 | D14: =$C$14*D13 -> 0 | E14: =$C$14*E13 -> 0 | F14: =$C$14*F13 -> 0 | G14: =$C$14*G13 -> 0 | H14: =$C$14*H13 -> 0 | I14: =$C$14*I13 -> 0
B16: INGRESOS NETOS DE MARCA | D16: =D13-D14 -> 0 | E16: =E13-E14 -> 0 | F16: =F13-F14 -> 0 | G16: =G13-G14 -> 0 | H16: =H13-H14 -> 0 | I16: =I13-I14 -> 0
B17: TASA DE IMPUESTOS | C17: 0.3 | D17: =+D16*$C$17 -> 0 | E17: =+E16*$C$17 -> 0 | F17: =+F16*$C$17 -> 0 | G17: =+G16*$C$17 -> 0 | H17: =+H16*$C$17 -> 0 | I17: =+I16*$C$17 -> 0
B19: AHORRO EN REGALÍAS NETO | D19: =+D16-D17 -> 0 | E19: =+E16-E17 -> 0 | F19: =+F16-F17 -> 0 | G19: =+G16-G17 -> 0 | H19: =+H16-H17 -> 0 | I19: =+I16-I17 -> 0
I20: =+((I19*(1+C24))/(C22-C24)) -> #VALUE!
B21: Tasa de Descuento Wacc | C21: =+'WACC_SECTOR GREEN ENERGY (2)'!G26 -> #VALUE!
B22: Van de los flujos de Royalty | C22: =+C21 -> #VALUE! | D22: =+D19/(1+$C$21)^D9 -> #VALUE! | E22: =+E19/(1+$C$21)^E9 -> #VALUE! | F22: =+F19/(1+$C$21)^F9 -> #VALUE! | G22: =+G19/(1+$C$21)^G9 -> #VALUE! | H22: =+H19/(1+$C$21)^H9 -> #VALUE! | I22: =+I20/(1+$C$21)^H9 -> #VALUE!
B24: G de largo plazo (expec. Inflaciíón) | C24: 0.0372
B26: Estimación del Valor de Marca | D26: =+SUM(D22:I22) -> #VALUE!
B31: Margen Superior Valor Marca | D31: =+D33*1.2 -> #VALUE!
B33: Estimación del Valor de Marca | D33: =ROUND(D26,-3) -> #VALUE!
B35: Margen Inferior Valor Marca | D35: =+D33*0.8 -> #VALUE!
B37: Beneficio Fiscal | D37: #REF!
B39: VALOR DE MARCA TOTAL | D39: =ROUND(D33*D37,-3) -> #VALUE!

Sheet Expected Growth25
A1: Date updated: | B1: 45662
A2: Created by: | B2: Aswath Damodaran, adamodar@stern.nyu.edu
A3: What is this data? | B3: Historical (compounded annual) growth rate in net income and revenues - last 5 years | F3: Global
A4: Home Page: | B4: http://www.damodaran.com
A5: Data website: | B5: https://pages.stern.nyu.edu/~adamodar/pc/datasets/histgr.xls
A6: Companies in each industry: | B6: https://pages.stern.nyu.edu/~adamodar/pc/datasets/indname.xls
A7: Variable definitions: | B7: https://pages.stern.nyu.edu/~adamodar/New_Home_Page/datafile/variable.htm
A8: Industry Name | B8: Number of Firms | C8: CAGR in Net Income- Last 5 years | D8: CAGR in Revenues- Last 5 years | E8: Expected Growth in Revenues - Next 2 years | F8: Expected Growth in Revenues - Next 5 years | G8: Expected Growth in EPS - Next 5 years
A9: Advertising | B9: 54 | C9: 0.1743 | D9: -0.0162 | E9: 0.0903 | F9: 0.0729 | G9: 0.2298
A10: Aerospace/Defense | B10: 67 | C10: 0.0349 | D10: 0.0821 | E10: 0.117 | F10: 0.1244 | G10: 0.1902
A11: Air Transport | B11: 24 | C11: -0.0359 | D11: 0.0264 | E11: 0.3829 | F11: 0.531 | G11: 0.3525
A12: Apparel | B12: 37 | C12: -0.0359 | D12: 0.0697 | E12: 0.0019 | F12: 0.0232 | G12: 0.0595
A13: Auto & Truck | B13: 34 | C13: 0.0837 | D13: 0.109 | E13: 0.9668 | F13: 0.3519 | G13: 0.1041
A14: Auto Parts | B14: 33 | C14: 0.0516 | D14: 0.0649 | E14: 0.1772 | F14: 0.0801 | G14: 0.1529
A15: Bank (Money Center) | B15: 15 | C15: -0.0436 | D15: 0.06 | E15: 0.0211 | F15: 0.0421 | G15: 0.1192
A16: Banks (Regional) | B16: 591 | C16: 0.046 | D16: 0.0654 | E16: 0.0704 | F16: 0.0507 | G16: 0.065
A17: Beverage (Alcoholic) | B17: 18 | C17: 0.1144 | D17: 0.0509 | E17: -0.0244 | F17: 0.0274 | G17: 0.1117
A18: Beverage (Soft) | B18: 29 | C18: 0.195 | D18: 0.1675 | E18: 0.0378 | F18: 0.0721 | G18: 0.1126
A19: Broadcasting | B19: 22 | C19: -0.0988 | D19: 0.0189 | E19: -0.0046 | F19: -0.0003 | G19: 1.9249
A20: Brokerage & Investment Banking | B20: 30 | C20: 0.1263 | D20: 0.2219 | E20: 0.1612 | F20: 0.071 | G20: 0.1537
... A24: Chemical (Basic) | B24: 31 | C24: 0.0253 | D24: 0.0867 | E24: 0.0408 | F24: 0.0023 | G24: 0.0762
A25: Chemical (Diversified) | B25: 4 | C25: -0.285 | D25: 0.0167 | E25: -0.0085 | F25: #DIV/0! | G25: 0.391
A26: Chemical (Specialty) | B26: 60 | C26: 0.0637 | D26: 0.0919 | E26: 0.188 | F26: 0.1352 | G26: 0.1042
A27: Coal & Related Energy | B27: 16 | C27: 0.2113 | D27: 0.0065 | E27: 4.2476 | F27: 0.6496 | G27: #DIV/0!
A28: Computer Services | B28: 63 | C28: 0.0427 | D28: 0.0934 | E28: 0.032 | F28: 0.3028 | G28: 0.1993
A29: Computers/Peripherals | B29: 35 | C29: 0.0679 | D29: 0.0355 | E29: 0.1036 | F29: 0.0426 | G29: 0.1148
A30: Construction Supplies | B30: 46 | C30: 0.2192 | D30: 0.0375 | E30: 6.1356 | F30: 0.0459 | G30: 0.1101
A31: Diversified | B31: 21 | C31: 0.0856 | D31: 0.1162 | E31: -0.028 | F31: 0.0113 | G31: 0.0544
A32: Drugs (Biotechnology) | B32: 535 | C32: 0.0109 | D32: 0.2377 | E32: 1.3639 | F32: 0.7235 | G32: 0.1795
A33: Drugs (Pharmaceutical) | B33: 231 | C33: -0.0296 | D33: 0.2478 | E33: 0.8018 | F33: 0.3705 | G33: 0.1221
A34: Education | B34: 29 | C34: 0.0579 | D34: 0.0477 | E34: 0.0651 | F34: 0.1131 | G34: 0.1688
A35: Electrical Equipment | B35: 101 | C35: 0.0539 | D35: 0.1329 | E35: 0.3731 | F35: 0.2807 | G35: 0.133
A36: Electronics (Consumer & Office) | B36: 11 | C36: 0 | D36: -0.07 | E36: -0.0402 | F36: #DIV/0! | G36: 0.225
A37: Electronics (General) | B37: 122 | C37: 0.1443 | D37: 0.1059 | E37: 0.1095 | F37: 0.1917 | G37: 0.1589
A38: Engineering/Construction | B38: 42 | C38: 0.227 | D38: 0.0865 | E38: 0.0927 | F38: 0.0618 | G38: 0.1682
A39: Entertainment | B39: 96 | C39: 0.1109 | D39: 0.1325 | E39: 0.0742 | F39: 0.0592 | G39: 0.1453
A40: Environmental & Waste Services | B40: 50 | C40: 0.0991 | D40: 0.1964 | E40: 0.3816 | F40: 0.0994 | G40: 0.1288
A41: Farming/Agriculture | B41: 35 | C41: 0.1486 | D41: 0.2223 | E41: 0.0493 | F41: 0.128 | G41: 0.0754
A42: Financial Svcs. (Non-bank & Insurance) | B42: 166 | C42: 0.0949 | D42: 0.1479 | E42: 0.1115 | F42: 0.0804 | G42: 0.1614
A43: Food Processing | B43: 77 | C43: 0.0511 | D43: 0.1002 | E43: 0.0489 | F43: 0.0318 | G43: 0.1036
...

Sheet MEDICION DE INGRESOS  (2)
F2: Growth(%) | G2: Crecimiento (%)
B3: EMPRESA | E3: Fuente | F3: Revenue Growth Rate (5Y) | G3: Revenue Growth Rate (3Y)*
B4: PayPal Holdings Inc | E4: https://www.reuters.com/markets/companies/pypl.o/financials/income-annual | F4: 0.1853 | G4: 0.1798 | M4: 55000
M5: 3
M6: =+M4/M5 -> 18333.333
B9: FORGUL, S.A. | E9: Promedio | F9: =AVERAGE(F4:F5) -> 0.1853 | G9: =AVERAGE(G4:G5) -> 0.1798
A12: En miles | B12: =+B4 -> PayPal Holdings Inc | C12: 43829 | D12: 44195 | E12: 44286 | F12: Crecimiento por Año | J12: Promedio | K12: CAGR
B13: Ingresos Totales | C13: 9785 | D13: 11453 | E13: 13450 | H13: =+E13/C13-1 -> 0.37455289 | J13: =AVERAGE(F13:I13) -> 0.37455289 | K13: =+(D13/C13)^(1/1)-1 -> 0.170465
B14: Utilidad Operativa | C14: 2719 | D14: 3289 | E14: 4262 | H14: =+E14/C14-1 -> 0.56748805 | J14: =+H14 -> 0.56748805 | K14: =+(D14/C14)^(1/1)-1 -> 0.2096359
B16: =+B5 -> 0 | C16: 44195 | D16: 44560 | E16: 44651 | F16: Crecimiento por Año | J16: Promedio | K16: CAGR
B17: Ingresos Totales | H17: =+D17/C17-1 -> #DIV/0! | I17: =+E17/D17-1 -> #DIV/0! | J17: =AVERAGE(F17:I17) -> #DIV/0! | K17: =+(D17/C17)^(1/1)-1 -> #DIV/0!
B18: Utilidad Operativa | H18: =+D18/C18-1 -> #DIV/0! | I18: =+E18/D18-1 -> #DIV/0! | J18: =AVERAGE(F18:I18) -> #DIV/0! | K18: =+(D18/C18)^(1/1)-1 -> #DIV/0!
B20: PLATAFORMA INMOBILIARIA CIEN LADRILLOS, S.A.P.I. DE C.V. | C20: 44195 | D20: 44560 | E20: 44651 | F20: Crecimiento por Año | J20: Promedio | K20: CAGR
B21: Ingresos Totales | K21: S/D
B22: Utilidad Operativa | K22: S/D
B24: =+B7 -> 0 | C24: 44195 | D24: 44560 | E24: 44651 | F24: Crecimiento por Año | J24: Promedio | K24: CAGR
B25: Ingresos Totales | H25: =+D25/C25-1 -> #DIV/0! | I25: =+E25/D25-1 -> #DIV/0! | J25: =AVERAGE(G25,I25,F25) -> #DIV/0! | K25: =+(E25/#REF!)^(1/3)-1 -> #REF!
B26: Utilidad Operativa | H26: =+D26/C26-1 -> #DIV/0! | I26: =+E26/D26-1 -> #DIV/0! | J26: =AVERAGE(G26) -> #DIV/0! | K26: =+(E26/#REF!)^(1/3)-1 -> #REF!
B28: =+B8 -> 0 | C28: 44195 | D28: 44560 | E28: 44651 | F28: Crecimiento por Año | J28: Promedio | K28: CAGR
B29: Ingresos Totales | H29: =+D29/C29-1 -> #DIV/0! | I29: =+E29/D29-1 -> #DIV/0! | J29: =AVERAGE(G29,F29) -> #DIV/0! | K29: =+(E29/#REF!)^(1/3)-1 -> #REF!
B30: Utilidad Operativa | H30: =+D30/C30-1 -> #DIV/0! | I30: =+E30/D30-1 -> #DIV/0! | J30: =AVERAGE(G30) -> #DIV/0! | K30: =+(E30/#REF!)^(1/3)-1 -> #REF!
B32: **Últimos 3 años. | G32: Crecimiento Promedio | J32: =AVERAGE(J13,J17) -> #DIV/0! | K32: =AVERAGE(K13,K17) -> #DIV/0!
G33: Crecimiento Promedio | J33: =AVERAGE(J14,J18) -> #DIV/0! | K33: =AVERAGE(K14,K18) -> #DIV/0!
A38: En miles | B38: =+B12 -> PayPal Holdings Inc | C38: 43464 | D38: 43829 | E38: 44195 | F38: Crecimiento por Año | J38: Promedio | K38: CAGR
B39: Total Revenue | C39: 12648 | D39: 17059 | E39: 4586 | H39: =+D39/C39-1 -> 0.34875079 | I39: =+E39/D39-1 -> -0.7311683 | J39: =AVERAGE(F39:I39) -> -0.19120875 | K39: =+(D39/C39)^(1/1)-1 -> 0.34875079
B40: Operating Income | C40: 12963 | D40: 17198 | E40: -279 | H40: =+D40/C40-1 -> 0.32669907 | I40: =+E40/D40-1 -> -1.0162228 | J40: =AVERAGE(F40:H40) -> 0.32669907 | K40: =+(D40/C40)^(1/1)-1 -> 0.32669907
C43: 43464 | D43: 43829 | E43: 44195 | F43: Crecimiento por Año | J43: Promedio | K43: CAGR
B44: Total Revenue | H44: =+D44/C44-1 -> #DIV/0! | I44: =+E44/D44-1 -> #DIV/0! | J44: =AVERAGE(F44:I44) -> #DIV/0! | K44: =+(D44/C44)^(1/1)-1 -> #DIV/0!
B45: Operating Income | H45: =+D45/C45-1 -> #DIV/0! | I45: =+E45/D45-1 -> #DIV/0! | J45: =AVERAGE(F45:H45) -> #DIV/0! | K45: =+(D45/C45)^(1/1)-1 -> #DIV/0!
B47: **Últimos 3 años. | G47: Crecimiento Promedio | J47: =AVERAGE(J39,J44) -> #DIV/0! | K47: =AVERAGE(K39,K44) -> #DIV/0!
G48: Crecimiento Promedio | J48: =AVERAGE(J40,J44) -> #DIV/0! | K48: =AVERAGE(K40,K44) -> #DIV/0!
B51: Análisis Vertical
A54: En miles | B54: =+B12 -> PayPal Holdings Inc | C54: 43465 | D54: 43830 | E54: 44196 | F54: Media
B55: Total Revenue | C55: =+C13/C13 -> 1 | D55: =+D13/D13 -> 1 | E55: =+E13/E13 -> 1 | F55: =AVERAGE(C55:E55) -> 1
B56: Operating Income | C56: =+C14/C13 -> 0.2778743 | D56: =+D14/D13 -> 0.28717367 | E56: =+E14/E13 -> 0.31687732 | F56: =AVERAGE(C56:D56) -> 0.28252398
A59: En miles | B59: =+B16 -> 0 | C59: 43465 | D59: 43830 | E59: 44196 | F59: Promedio*
B60: Total Revenue | C60: =+C17/C17 -> #DIV/0! | D60: =+D17/D17 -> #DIV/0! | E60: =+E17/E17 -> #DIV/0! | F60: 1
B61: Operating Income | C61: =+C18/C17 -> #DIV/0! | D61: =+D18/D17 -> #DIV/0! | E61: =+E18/E17 -> #DIV/0! | F61: =AVERAGE(C61:D61) -> #DIV/0!
D63: Promedio Sector | F63: =+AVERAGE(F56,F61) -> #DIV/0!

Sheet VALOR NETO CONTABLE
B3: VALOR CONTABLE | E3: VALOR CONTABLE
B4: ACTIVOS | E4: ACTIVOS
B5: Efectivo y bancos | C5: =+'1. Datos'!J45 -> 0 | E5: Efectivo y bancos
B6: Clientes | C6: =+'1. Datos'!J46 -> 0 | E6: Clientes
B7: Inventarios | C7: =+'1. Datos'!J47 -> 0 | E7: Deudores Diversos
B8: Inversiones | C8: =+'1. Datos'!J55 -> 0 | E8: Impuestos a Favor
B9: Mobiliario y Equipo Neto | C9: =+'1. Datos'!J64 -> 0 | E9: Inventarios
B10: Otros activos | C10: =+'1. Datos'!J48 -> 0 | E10: Bienes inmobiliarios
E11: Dep. En Garantia
B13: TOTAL DE ACTIVOS | C13: =+SUM(C5:C12) -> 0 | E13: TOTAL DE ACTIVOS | F13: =+SUM(F5:F11) -> 0
B15: PASIVOS | E15: PASIVOS
B16: Acreedores Diversos | C16: =+'1. Datos'!J105+'1. Datos'!J113 -> 0 | E16: Proveedores
B17: Impuestos y Derechos por pagar | C17: =+'1. Datos'!J106 -> 0 | E17: Acreedores a corto plazo
B18: Otros pasivos | C18: =+'1. Datos'!J107 -> 0 | E18: Impuestos por pagar
B19: Documentos por pagar | E19: Otros Pasivos
E20: TOTAL DE PASIVOS
B21: TOTAL DE PASIVOS | C21: =SUM(C16:C20) -> 0
E22: VALOR NETO CONTABLE | F22: =+F10-F20 -> 0
B23: VALOR NETO CONTABLE | C23: =+C13-C21 -> 0

Sheet 1. Datos
C2: GRUPO OVANDO CONTRUCCIÓN- IMOBILIARIA- TRANSPORTES S.A. de C.V.
C3: Estado de Resultados
G4: =G6/F6-1 -> #DIV/0! | H4: =H6/G6-1 -> #DIV/0! | I4: =I6/H6-1 -> #DIV/0! | K4: =K6/I6-1 -> #DIV/0! | L4: =+AVERAGE(F4:K4) -> #DIV/0!
D5: 2019 | E5: =+D5+1 -> 2020 | F5: =E5+1 -> 2021 | G5: =F5+1 -> 2022 | H5: =G5+1 -> 2023 | I5: =H5+1 -> 2024 | J5: 2025 | K5: 2025 proyecctado
C6: Ventas | K6: =+L6*12 -> 0 | L6: =+J6/9 -> 0
L7: =+J7/9 -> 0
C8: VENTAS NETAS | D8: =+D6-D7 -> 0 | E8: =+E6-E7 -> 0 | F8: =+F6-F7 -> 0 | G8: =+G6-G7 -> 0 | H8: =+H6-H7 -> 0 | I8: =+I6-I7 -> 0 | J8: =+J6-J7 -> 0 | K8: =+K6-K7 -> 0 | L8: =+J8/9 -> 0
C9: Costo de Ventas | D9: 0 | L9: =+J9/9 -> 0
C10: UTILIDAD BRUTA | D10: =+D8-D9 -> 0 | E10: =+E8-E9 -> 0 | F10: =+F8-F9 -> 0 | G10: =+G8-G9 -> 0 | H10: =+H8-H9 -> 0 | I10: =+I8-I9 -> 0 | J10: =+J8-J9 -> 0 | K10: =+K8-K9 -> 0 | L10: =+J10/9 -> 0
L11: =+J11/9 -> 0
C12: COSTOS Y GASTOS | D12: =SUM(D13:D17) -> 0 | E12: =SUM(E13:E17) -> 0 | L12: =+J12/9 -> 0 | M12: =7859990-J9 -> 7859990
C13: Gastos de operación | L13: =+J13/9 -> 0
C14: Gastos generales | L14: =+J14/9 -> 0
C15: Gastos de administracion | L15: =+J15/9 -> 0
L16: =+J16/9 -> 0
K17: =(I17/4)*12 -> 0 | L17: =+J17/9 -> 0
L18: =+J18/9 -> 0
C19: UITILIDAD DE LA OPERACIÓN | D19: =+D10-D12 -> 0 | E19: =+E10-E12 -> 0 | F19: =+F10-F12 -> 0 | G19: =+G10-G12 -> 0 | H19: =+H10-H12 -> 0 | I19: =+I10-I12 -> 0 | J19: =+J10-J12 -> 0 | K19: =+K10-K12 -> 0 | L19: =+J19/9 -> 0
C20: Otros Gastos | D20: 0 | G20: 0 | H20: 0 | I20: 0 | J20: 0 | K20: 0 | L20: =+J20/9 -> 0
C21: Otros Ingresos | L21: =+J21/9 -> 0 | M21: 288830
L22: =+J22/9 -> 0
L23: =+J23/9 -> 0
C24: RESULTADO INTEGRAL DE FINANCIAMIENTO | D24: =SUM(D20:D21) -> 0 | E24: =SUM(E20:E23) -> 0 | F24: =SUM(F20:F23) -> 0 | G24: =SUM(G20:G23) -> 0 | H24: =SUM(H20:H23) -> 0 | I24: =SUM(I20:I23) -> 0 | J24: =SUM(J20:J23) -> 0 | K24: =SUM(K20:K23) -> 0 | L24: =+J24/10 -> 0
C25: ISR diferido | L25: =+J25/10 -> 0
C26: ISR | D26: 0 | L26: =+J26/10 -> 0
C27: Provision de PTU | L27: =+J27/10 -> 0
L28: =+J28/10 -> 0
C29: Total Impts | D29: =SUM(D25:D28) -> 0 | E29: =SUM(E25:E28) -> 0 | F29: =SUM(F25:F28) -> 0 | G29: =SUM(G25:G28) -> 0 | H29: =SUM(H25:H28) -> 0 | I29: =SUM(I25:I27) -> 0 | J29: =SUM(J25:J28) -> 0 | K29: =SUM(K25:K27) -> 0
C30: UTILDIDAD O PERDIDA NETA DEL AÑO | D30: =D19+D24-D29 -> 0 | E30: =E19+E24-E29 -> 0 | F30: =F19+F24-F29 -> 0 | G30: =G19+G24-G29 -> 0 | H30: =H19+H24-H29 -> 0 | I30: =I19+I24-I29 -> 0 | J30: =J19+J24-J29 -> 0 | K30: =K19+K24-K29 -> 0
C33: =#REF! -> #REF! | D33: =+D5 -> 2019 | E33: =+E5 -> 2020 | G33: =+G5 -> 2022
C34: =#REF! -> #REF! | D34: =#REF! -> #REF! | E34: =#REF! -> #REF! | G34: =#REF! -> #REF!
C35: =#REF! -> #REF! | D35: =#REF! -> #REF! | E35: =#REF! -> #REF! | G35: =#REF! -> #REF!
C36: =#REF! -> #REF! | D36: =#REF! -> #REF! | E36: =#REF! -> #REF! | G36: =#REF! -> #REF!
C39: =+C2 -> GRUPO OVANDO CONTRUCCIÓN- IMOBILIARIA- TRANSPORTES S.A. de C.V.
D42: 2019 | E42: =+D42+1 -> 2020 | F42: =E42+1 -> 2021 | G42: =F42+1 -> 2022 | H42: =G42+1 -> 2023 | I42: 2024 | J42: =+I42+1 -> 2025
C43: ACTIVO
C44: Activo Circulante | D44: =SUM(D45:D63) -> 0 | E44: =SUM(E45:E63) -> 6046273
C45: Efectivo y equivalentes de efectivo
C46: Cuentas por cobrar
C47: Impuestos a favor
...

Sheet 2.Cálculos (2)
C5: 2019 | D5: =+C5+1 -> 2020 | E5: =+D5+1 -> 2021 | F5: =+E5+1 -> 2022 | G5: =+F5+1 -> 2023 | H5: 2024 | I5: 2025
B6: Utilidad Neta | C6: ='1. Datos'!D30 -> 0 | D6: ='1. Datos'!E30 -> 0 | E6: ='1. Datos'!F30 -> 0 | F6: ='1. Datos'!G30 -> 0 | G6: ='1. Datos'!H30 -> 0 | H6: ='1. Datos'!I30 -> 0 | I6: ='1. Datos'!J30 -> 0
B7: Capital Total | C7: =+'1. Datos'!D135 -> 0 | D7: =+'1. Datos'!E135 -> 0 | E7: =+'1. Datos'!F135 -> 0 | F7: =+'1. Datos'!G135 -> 0 | G7: =+'1. Datos'!H135 -> 0 | H7: =+'1. Datos'!I135 -> 0 | I7: =+'1. Datos'!J135 -> 0
B8: ROE | C8: =C6/C7 -> #DIV/0! | D8: =D6/D7 -> #DIV/0! | E8: =E6/E7 -> #DIV/0! | F8: =F6/F7 -> #DIV/0! | G8: =G6/G7 -> #DIV/0! | H8: =H6/H7 -> #DIV/0! | I8: =I6/I7 -> #DIV/0! | K8: Promedio de reinversión | N8: =AVERAGE(E11:H11) -> #DIV/0!
B9: Dividendos | C9: 0 | D9: 0 | E9: 0 | F9: 0 | G9: 0 | H9: 0 | I9: 0
B10: % de Dividendos | C10: =C9/C6 -> #DIV/0! | D10: =D9/D6 -> #DIV/0! | E10: =E9/E6 -> #DIV/0! | F10: =F9/F6 -> #DIV/0! | G10: =G9/G6 -> #DIV/0! | H10: =H9/H6 -> #DIV/0! | I10: =I9/I6 -> #DIV/0!
B11: Tasa de Reinversión | C11: =1-C10 -> #DIV/0! | D11: =1-D10 -> #DIV/0! | E11: =1-E10 -> #DIV/0! | F11: =1-F10 -> #DIV/0! | G11: =1-G10 -> #DIV/0! | H11: =1-H10 -> #DIV/0! | I11: =1-I10 -> #DIV/0! | K11: Crecimiento (g) Promedio | N11: =+AVERAGE(F12:I12) -> #DIV/0!
B12: Crecimiento (g) | C12: =C8*C11 -> #DIV/0! | D12: =D8*D11 -> #DIV/0! | E12: =E8*E11 -> #DIV/0! | F12: =F8*F11 -> #DIV/0! | G12: =G8*G11 -> #DIV/0! | H12: =H8*H11 -> #DIV/0! | I12: =I8*I11 -> #DIV/0!
B14: CAMBIO NETO EN CAPITAL DE TRABAJO OPERATIVO | L14: mediageom | N14: =+GEOMEAN(F12,I12) -> #DIV/0!
K15: ROE=
B17: Activo Circulante | C17: =+'1. Datos'!D44 -> 0 | D17: =+'1. Datos'!E44 -> 6046273 | E17: =+'1. Datos'!F44 -> 0 | F17: =+'1. Datos'!G44 -> 0 | G17: =+'1. Datos'!H44 -> 0 | H17: =+'1. Datos'!I44 -> 0 | I17: =+'1. Datos'!J44 -> 0
B18: Pasivo Circulante | C18: =+'1. Datos'!D104 -> 0 | D18: =+'1. Datos'!E104 -> 0 | E18: =+'1. Datos'!F104 -> 0 | F18: =+'1. Datos'!G104 -> 0 | G18: =+'1. Datos'!H104 -> 0 | H18: =+'1. Datos'!I104 -> 0 | I18: =+'1. Datos'!J104 -> 0
B19: Capital de Trabajo (AC-PC) | C19: =+C17-C18 -> 0 | D19: =+D17-D18 -> 6046273 | E19: =+E17-E18 -> 0 | F19: =+F17-F18 -> 0 | G19: =+G17-G18 -> 0 | H19: =+H17-H18 -> 0 | I19: =+I17-I18 -> 0
A20: 3 | B20: Δ Capital de Trabajo | C20: =C19 -> 0 | D20: =D19 -> 6046273 | E20: =E19 -> 0 | F20: =F19 -> 0 | G20: =G19 -> 0 | H20: =H19 -> 0 | I20: =I19 -> 0 | N20: =AVERAGE(D21:H21) -> #DIV/0!
C21: 0 | F21: =+F22/E22-1 -> #DIV/0! | G21: =+G22/F22-1 -> #DIV/0! | H21: =+H22/G22-1 -> #DIV/0! | I21: =+I22/H22-1 -> #DIV/0!
B22: Utilidad de Operación (EBIT) | C22: =+'1. Datos'!D19 -> 0 | D22: =+'1. Datos'!E19 -> 0 | E22: =+'1. Datos'!F19 -> 0 | F22: =+'1. Datos'!G19 -> 0 | G22: =+'1. Datos'!H19 -> 0 | H22: =+'1. Datos'!I19 -> 0 | I22: =+'1. Datos'!K19 -> 0
B23: Impuestos (Tax) | C23: =+'1. Datos'!D25 -> 0 | D23: =+'1. Datos'!E25 -> 0 | E23: =+'1. Datos'!F25 -> 0 | F23: =+'1. Datos'!G25 -> 0 | G23: =+'1. Datos'!H25 -> 0 | H23: =+'1. Datos'!I25 -> 0 | I23: =+'1. Datos'!J25 -> 0
B24: Utilidad Antes de Impuestos | C24: =+C22 -> 0 | D24: =+D22 -> 0 | E24: =+E22 -> 0 | F24: =+F22 -> 0 | G24: =+G22 -> 0 | H24: =+H22 -> 0 | I24: =+I22 -> 0
B25: Tasa Impositiva (t) | C25: 0.3 | D25: 0.3 | E25: 0.3 | F25: 0.3 | G25: 0.3 | H25: 0.3 | I25: 0.3
B26: EBIT*(1-t) | C26: =C22*(1-C25) -> 0 | D26: =D22*(1-D25) -> 0 | E26: =E22*(1-E25) -> 0 | F26: =F22*(1-F25) -> 0 | G26: =G22*(1-G25) -> 0 | H26: =H22*(1-H25) -> 0 | I26: =I22*(1-I25) -> 0
B27: Depreciación | C27: 0 | D27: =-'1. Datos'!E98 -> 0 | E27: =+-'1. Datos'!F98 -> 0 | F27: =+-'1. Datos'!G98 -> 0 | G27: =+-'1. Datos'!H98 -> 0 | H27: =+-'1. Datos'!I98 -> 0 | I27: =+-'1. Datos'!J98 -> 0
B28: Flujo Bruto de Efectivo (FBE) | C28: =C27+C26 -> 0 | D28: =D27+D26 -> 0 | E28: =E27+E26 -> 0 | F28: =F27+F26 -> 0 | G28: =G27+G26 -> 0 | H28: =H27+H26 -> 0 | I28: =I27+I26 -> 0
B30: Δ Capital de Trabajo | C30: =+C20 -> 0 | D30: =+D20 -> 6046273 | E30: =+E20 -> 0 | F30: =+F20 -> 0 | G30: =+G20 -> 0 | H30: =+H20 -> 0 | I30: =+I20 -> 0
B31: Depreciación | C31: 0 | D31: =D27 -> 0 | E31: =E27 -> 0 | F31: =F27 -> 0 | G31: =G27 -> 0 | H31: =H27 -> 0 | I31: =I27 -> 0
B32: Capex | C32: ='2.Cálculos (2)'!C81 -> 0 | D32: ='2.Cálculos (2)'!C81 -> 0 | E32: =+E81 -> 0 | F32: =+F81 -> 0 | G32: =+G81 -> 0 | H32: =+H81 -> 0 | I32: =+I81 -> 0
B33: Incremento Otros Activos
B34: =B28 -> Flujo Bruto de Efectivo (FBE) | C34: =C28 -> 0 | D34: =D28 -> 0 | E34: =E28 -> 0 | F34: =F28 -> 0 | G34: =G28 -> 0 | H34: =H28 -> 0 | I34: =I28 -> 0
B35: Inversión Bruta | C35: =C33+C32+C30 -> 0 | D35: =D33+D32+D30 -> 6046273 | E35: =E33+E32+E30 -> 0 | F35: =F33+F32+F30 -> 0 | G35: =G33+G32+G30 -> 0 | H35: =H33+H32+H30 -> 0 | I35: =I33+I32+I30 -> 0
B36: Flujo de Caja Libre (FCF) | C36: =C34-C35 -> 0 | D36: =D34-D35 -> -6046273 | E36: =E34-E35 -> 0 | F36: =F34-F35 -> 0 | G36: =G34-G35 -> 0 | H36: =H34-H35 -> 0 | I36: =I34-I35 -> 0 | K36: Promedio de FCF% | N36: =AVERAGE(D37:I37) -> #DIV/0!
B37: FCF% = FCF / EBIT(1-t) | C37: =1-(C35)/C34 -> #DIV/0! | D37: =1-(D34)/D35 -> 1 | E37: =1-(E26)/E36 -> #DIV/0! | F37: =1-(F26)/F36 -> #DIV/0! | G37: =1-(G26)/G36 -> #DIV/0! | H37: =1-(H26)/H36 -> #DIV/0! | I37: =1-(I36)/I35 -> #DIV/0!
B38: Reinversión (1-FCF%) | C38: =1-C37 -> #DIV/0! | D38: =1-D37 -> 0 | E38: =1-E37 -> #DIV/0! | F38: =1-F37 -> #DIV/0! | G38: =1-G37 -> #DIV/0! | H38: =1-H37 -> #DIV/0! | I38: =1-I37 -> #DIV/0!
K39: Promedio de Reinversión% | N39: =AVERAGE(D38:I38) -> #DIV/0!
B44: Rentabilidad = EBIT / CAPITAL
D47: 0.56719583 | E47: 0.91954389
B51: NO SE OCUPA
B52: NO SE OCUPA | C52: =+C5 -> 2019 | D52: =+D5 -> 2020 | E52: =+E5 -> 2021 | F52: =+F5 -> 2022
B53: Activo Circulante
B54: #REF! | C54: #ERROR! | D54: #REF! | E54: #REF! | F54: #REF!
B55: (Incremento) de efectivo operativo | C55: =C54-#REF! -> #VALUE! | D55: =D54-#REF! -> #REF! | E55: =E54-D54 -> #REF! | F55: =F54-E54 -> #REF!
B56: #ERROR! | C56: #ERROR! | D56: #ERROR! | E56: #ERROR! | F56: #ERROR!
...

Sheet MARCA
B1: VALOR DE MARCA | M1: RANGO DE REGALIAS
B2: INGRESOS REALES | N2: MIN | O2: MAX
M3: 0.025 | N3: 0.05
C4: 2020 | D4: =+C4+1 -> 2021 | E4: =+D4+1 -> 2022 | F4: =+E4+1 -> 2023 | G4: =+F4+1 -> 2024 | H4: =+G4+1 -> 2025 | J4: CAGR | K4: Sector | L4: CAGR Empresa | M4: MEDIA
B5: INGRESOS HISTORICOS PESOS CORRIENTES | C5: =+'1. Datos'!E6 -> 0 | D5: =+'1. Datos'!F6 -> 0 | E5: =+'1. Datos'!G6 -> 0 | F5: =+'1. Datos'!H6 -> 0 | G5: =+'1. Datos'!I6 -> 0 | H5: =+'1. Datos'!K6 -> 0 | J5: =+(H5/E5)^(1/4)-1 -> #DIV/0! | K5: =+'Expected Growth25'!E38 -> 0.0927 | L5: =+AVERAGE(F6:H6) -> #DIV/0! | M5: =+N3/2 -> 0.025
B6: INCREMENTOS | E6: =+E5/D5-1 -> #DIV/0! | F6: =+F5/E5-1 -> #DIV/0! | G6: =+G5/F5-1 -> #DIV/0! | H6: =+H5/G5-1 -> #DIV/0!
N8: Tasa de Regalía | O8: Homologación
B9: PROYECCIÓN | C9: PARAMETROS | D9: 0.5 | E9: 1.5 | F9: 2.5 | G9: 3.5 | H9: 4.5 | I9: VT | M9: =+M5 -> 0.025
B10: AÑOS | D10: 2026 | E10: =+D10+1 -> 2027 | F10: =+E10+1 -> 2028 | G10: =+F10+1 -> 2029 | H10: =+G10+1 -> 2030 | I10: =+H10 -> 2030 | M10: Eficiencia Operativa | N10: -0.4
B11: CRECIMIENTO SECTOR | D11: =+K5 -> 0.0927 | E11: =D11 -> 0.0927 | F11: =+'Expected Growth25'!F38 -> 0.0618 | G11: =+F11 -> 0.0618 | H11: =+G11 -> 0.0618 | I11: =H11 -> 0.0618 | N11: =+M5*(1+N10) -> 0.015
B12: INGRESOS | D12: =+H5*(1+D11) -> 0 | E12: =+D12*(1+E11) -> 0 | F12: =+E12*(1+F11) -> 0 | G12: =+F12*(1+G11) -> 0 | H12: =+G12*(1+H11) -> 0 | I12: =+H12 -> 0 | K12: -
B13: AHORRO EN REGALÍAS | C13: 0.025 | D13: =+D12*$C$13 -> 0 | E13: =+E12*$C$13 -> 0 | F13: =+F12*$C$13 -> 0 | G13: =+G12*$C$13 -> 0 | H13: =+H12*$C$13 -> 0 | I13: =+I12*$C$13 -> 0
B14: GASTO POR MANTENIMIENTO | C14: 0.05 | D14: =$C$14*D13 -> 0 | E14: =$C$14*E13 -> 0 | F14: =$C$14*F13 -> 0 | G14: =$C$14*G13 -> 0 | H14: =$C$14*H13 -> 0 | I14: =$C$14*I13 -> 0
B16: INGRESOS NETOS DE MARCA | D16: =D13-D14 -> 0 | E16: =E13-E14 -> 0 | F16: =F13-F14 -> 0 | G16: =G13-G14 -> 0 | H16: =H13-H14 -> 0 | I16: =I13-I14 -> 0
B17: TASA DE IMPUESTOS | C17: 0.3 | D17: =+D16*$C$17 -> 0 | E17: =+E16*$C$17 -> 0 | F17: =+F16*$C$17 -> 0 | G17: =+G16*$C$17 -> 0 | H17: =+H16*$C$17 -> 0 | I17: =+I16*$C$17 -> 0
B19: AHORRO EN REGALÍAS NETO | D19: =+D16-D17 -> 0 | E19: =+E16-E17 -> 0 | F19: =+F16-F17 -> 0 | G19: =+G16-G17 -> 0 | H19: =+H16-H17 -> 0 | I19: =+((H19*(1+C24))/(C22-C24)) -> 0
B21: Tasa de Descuento Wacc | C21: =+WACC!K26+0.01 -> 0.16953943
B22: Van de los flujos de Royalty | C22: =+C21 -> 0.16953943 | D22: =+D19/(1+$C$21)^D9 -> 0 | E22: =+E19/(1+$C$21)^E9 -> 0 | F22: =+F19/(1+$C$21)^F9 -> 0 | G22: =+G19/(1+$C$21)^G9 -> 0 | H22: =+H19/(1+$C$21)^H9 -> 0 | I22: =+I19/(1+$C$21)^H9 -> 0
B24: G de largo plazo (expec. Inflaciíón) | C24: =+'4.Resumen-Escenario'!AU18 -> 0.0443
B26: Estimación del Valor de Marca | D26: =+ROUND(SUM(D22:I22),-3) -> 0
B29: Margen Superior Valor Marca | D29: =+D31*1.2 -> 0
B31: Margen Inferior Valor Marca | D31: =ROUND(D26,-3) -> 0
B33: Beneficio Fiscal | D33: =+'BENEFICIO FISCAL'!O30 -> #DIV/0!
B35: VALOR DE MARCA TOTAL | D35: =ROUND(D31*D33,3) -> #DIV/0!

Sheet 4.Resumen-Escenario1
X2: Tasa Crecimiento ROE/Dividendos
P3: FLUJOS DE EFECTIVO | X3: ='Expected Growth25'!E66 -> 0.0196 | AC3: Modelo a Perpetuidad (Conservador) | BG3: Modelo de Ventaja Competitiva
O4: DIRECCION Y CONTROL DE FRANQUICIAS S.A DE C.V | AP4: =+O4 -> DIRECCION Y CONTROL DE FRANQUICIAS S.A DE C.V
M5: HISTÓRICO | X5: G SECTOR 2 YEARS | AA5: PROYECCIÓN | AP5: PROYECCIÓN | AU5: VT | BF5: PROYECCIÓN
M6: 1 | N6: 1 | O6: 1 | P6: 1 | Q6: 2 | R6: 3 | S6: 4 | T6: 5 | U6: 6 | X6: ='Expected Growth25'!E66 -> 0.0196 | AA6: 1 | AB6: 2 | AC6: 3 | AD6: 4 | AE6: 5 | AF6: 5 | AM6: 0 | AP6: 1 | AQ6: 2 | AR6: 3 | AS6: 4 | AT6: 5 | AU6: 5 | BF6: 1 | BG6: 2 | BH6: 3 | BI6: 4 | BJ6: 5 | BK6: 5 | BM6: Tasa de Crecimiento para Perpetuidad**
M7: 2014 | N7: 2015 | O7: 2018 | P7: 2019 | Q7: =+P7+1 -> 2020 | R7: =+Q7+1 -> 2021 | S7: 2022 | T7: 2023 | U7: 2024 | AP7: 2025 | AQ7: =+AP7+1 -> 2026 | AR7: =+AQ7+1 -> 2027 | AS7: =+AR7+1 -> 2028 | AT7: =+AS7+1 -> 2029 | AU7: =+AT7 -> 2029 | AW7: Tasa de Crecimiento para Perpetuidad** | BF7: =+AA7 -> 0 | BG7: =+AB7 -> 0 | BH7: =+AC7 -> 0 | BI7: =+AD7 -> 0 | BJ7: =+AE7 -> 0 | BK7: =+BJ7 -> 0 | BM7: 0.04
Q8: =+Q11/P11-1 -> #REF! | R8: =+R11/Q11-1 -> #REF! | S8: =+S11/R11-1 -> #DIV/0! | T8: =+T11/S11-1 -> #DIV/0! | U8: =+U11/T11-1 -> #DIV/0! | BF8: =+AP8 -> 0 | BG8: =+BF8*(1+BG9) -> 0 | BH8: =+BG8*(1+BH9) -> 0 | BI8: =+BH8*(1+BI9) -> 0 | BJ8: =+BI8*(1+BJ9) -> 0 | BK8: =+BJ8*(1+BK9) -> 0
AW9: 0.0465 | BC9: G crecimiento | BF9: 0.1833 | BG9: =0.1825*(BG6)^(-0.253) -> 0.15314481 | BH9: =0.1825*(BH6)^(-0.253) -> 0.13821373 | BI9: =0.1825*(BI6)^(-0.253) -> 0.12851141 | BJ9: =0.1825*(BJ6)^(-0.253) -> 0.12145725 | BK9: =0.1825*(BK6)^(-0.253) -> 0.12145725 | BM9: **Variación Anual Promedio INPC útlimos 9 años
J11: EBIT | M11: #ERROR! | N11: #REF! | O11: =+'1. Datos'!D15 -> 0 | P11: =+'1. Datos'!#REF! -> #REF! | Q11: =+'1. Datos'!#REF! -> #REF! | R11: =+'1. Datos'!E15 -> 0 | S11: =+'1. Datos'!F15 -> 0 | T11: =+'1. Datos'!G15 -> 0 | U11: =+'1. Datos'!I15 -> 0 | X11: WACC | AA11: =+#REF! -> #REF! | AM11: WACC | AP11: =WACC!G28 -> #DIV/0! | AX11: Inflacion | BC11: WACC | BF11: =+AP11 -> #DIV/0! | BM11: Reinversion= | BN11: #REF!
AY12: Se tomo en consideracion la tasa inflacionaria de 3.65% de acuerdo con las perspectivas de inflacion de Banco Mexico
J14: t | M14: 0.3 | N14: 0.3 | O14: 0.3 | P14: 0.3 | Q14: 0.3 | R14: 0.3 | S14: 0.3 | T14: 0.3 | U14: 0.3 | AF14: =+(AE15*(1+X3))/AA11 -> #REF! | AM14: G | AN14: =AP18 -> #DIV/0!
J15: NOPAT = EBIT (1-t) | M15: =M11*(1-M14) -> #VALUE! | N15: =N11*(1-N14) -> #REF! | O15: =O11*(1-O14) -> 0 | P15: =P11*(1-P14) -> #REF! | Q15: =Q11*(1-Q14) -> #REF! | R15: =R11*(1-R14) -> 0 | S15: =S11*(1-S14) -> 0 | T15: =T11*(1-T14) -> 0 | U15: =U11*(1-U14) -> 0 | X15: EBIT (1-t) | AA15: =+AA8*$U$16 -> 0 | AB15: =+AB8*$U$16 -> 0 | AC15: =+AC8*$U$16 -> 0 | AD15: =+AD8*$U$16 -> 0 | AE15: =+AE8*$U$16 -> 0 | AF15: =+(AF8*$U$16)/AA11 -> #REF! | AM15: EBIT (1-t) | AP15: =+U15 -> 0 | AQ15: =+AP19 -> #DIV/0! | AR15: =+AQ19 -> #DIV/0! | AS15: =+AR19 -> #DIV/0! | AT15: =+AS19 -> #DIV/0! | AU15: =+AT19 -> #DIV/0! | BC15: EBIT (1-t) | BF15: =+BF8*$U$16 -> 0 | BG15: =+BG8*$U$16 -> 0 | BH15: =+BH8*$U$16 -> 0 | BI15: =+BI8*$U$16 -> 0 | BJ15: =+BJ8*$U$16 -> 0 | BK15: =((BK8*$U$16)*(1-(X3/BN11))/(BF11-BM7)) -> #REF!
J18: DEPRECIACIÓN | M18: #REF! | N18: 0 | O18: ='2.Cálculos (2)'!C26 -> 0 | P18: =+'2.Cálculos (2)'!#REF! -> #REF! | Q18: =+'2.Cálculos (2)'!D27 -> 0 | R18: =+'2.Cálculos (2)'!E27 -> 0 | S18: =+'2.Cálculos (2)'!F27 -> 0 | T18: =+'2.Cálculos (2)'!G27 -> 0 | U18: =+'2.Cálculos (2)'!H27 -> 0 | AP18: ='1. Datos'!L192 -> #DIV/0! | AQ18: =+AP18 -> #DIV/0! | AR18: =+AQ18 -> #DIV/0! | AS18: =+AR18 -> #DIV/0! | AT18: =+AS18 -> #DIV/0! | AU18: =+AT18 -> #DIV/0! | AW18: Valor Terminal = NOPLAT (1+g)
J19: FLUJO BRUTO DE EFECTIVO (FBE) | M19: =M15+M18 -> #VALUE! | N19: =N15+N18 -> #REF! | O19: =O15+O18 -> 0 | P19: =P15+P18 -> #REF! | Q19: =Q15+Q18 -> #REF! | R19: =R15+R18 -> 0 | S19: =S15+S18 -> 0 | T19: =T15+T18 -> 0 | U19: =U15+U18 -> 0 | X19: EBIT (1-t) | AA19: =AA15*(1+AA18) -> 0 | AB19: =AB15*(1+AB18) -> 0 | AC19: =AC15*(1+AC18) -> 0 | AD19: =AD15*(1+AD18) -> 0 | AE19: =AE15*(1+AE18) -> 0 | AF19: =AF15*(1+AF18) -> #REF! | AM19: FLUJO PROYECTADO = EBIT(1-T)* (1+g) | AP19: =AP15*(1+AP18) -> #DIV/0! | AQ19: =AQ15*(1+AQ18) -> #DIV/0! | AR19: =AR15*(1+AR18) -> #DIV/0! | AS19: =AS15*(1+AS18) -> #DIV/0! | AT19: =AT15*(1+AT18) -> #DIV/0! | AU19: =+(AU15*(1+AU18))/(AP11-AW9) -> #DIV/0! | AX19: WACC -g | BC19: FLUJO PROYECTADO = EBIT(1-T)* (1+g) | BF19: =BF15*(1+BF18) -> 0 | BG19: =BG15*(1+BG18) -> 0 | BH19: =BH15*(1+BH18) -> 0 | BI19: =BI15*(1+BI18) -> 0 | BJ19: =BJ15*(1+BJ18) -> 0 | BK19: =BK15*(1+BK18) -> #REF!
J21: ='2.Cálculos (2)'!B20 -> Δ Capital de Trabajo | O21: =+'2.Cálculos (2)'!C30 -> 0 | P21: =+'2.Cálculos (2)'!#REF! -> #REF! | Q21: =+'2.Cálculos (2)'!D30 -> 6046273 | R21: =+'2.Cálculos (2)'!E30 -> 0 | S21: =+'2.Cálculos (2)'!F30 -> 0 | T21: =+'2.Cálculos (2)'!G30 -> 0 | U21: =+'2.Cálculos (2)'!H30 -> 0 | X21: VALOR TERMINAL | AA21: =AF19 -> #REF! | AM21: VALOR TERMINAL | AP21: =AU19 -> #DIV/0! | BC21: VALOR TERMINAL | BF21: =BK19 -> #REF!
J22: ='2.Cálculos (2)'!B32 -> Capex | O22: =+'2.Cálculos (2)'!C32 -> 0 | P22: =+'2.Cálculos (2)'!#REF! -> #REF! | Q22: =+'2.Cálculos (2)'!D32 -> 0 | R22: =+'2.Cálculos (2)'!E32 -> 0 | S22: =+'2.Cálculos (2)'!F32 -> 0 | T22: =+'2.Cálculos (2)'!G32 -> 0 | U22: =+'2.Cálculos (2)'!H32 -> 0
X23: FCF | AA23: =AA19*$O$32 -> #DIV/0! | AB23: =AB19*$O$32 -> #DIV/0! | AC23: =AC19*$O$32 -> #DIV/0! | AD23: =AD19*$O$32 -> #DIV/0! | AE23: =AE19*$O$32 -> #DIV/0! | AF23: =AF19*$O$32 -> #REF! | AM23: FCF | AP23: =AP19*$O$37 -> #DIV/0! | AQ23: =AQ19*$O$37 -> #DIV/0! | AR23: =AR19*$O$37 -> #DIV/0! | AS23: =AS19*$O$37 -> #DIV/0! | AT23: =AT19*$O$37 -> #DIV/0! | AU23: =AU19*$O$37 -> #DIV/0! | BC23: FCF | BF23: =BF19*$O$32 -> #DIV/0! | BG23: =BG19*$O$32 -> #DIV/0! | BH23: =BH19*$O$32 -> #DIV/0! | BI23: =BI19*$O$32 -> #DIV/0! | BJ23: =BJ19*$O$32 -> #DIV/0! | BK23: =BK19*$O$32 -> #REF!
J24: INVERSION BRUTA | O24: =SUM(O21:O23) -> 0 | P24: =SUM(P21:P23) -> #REF! | Q24: =SUM(Q21:Q23) -> 6046273 | R24: =SUM(R21:R23) -> 0 | S24: =SUM(S21:S23) -> 0 | T24: =SUM(T21:T23) -> 0 | U24: =SUM(U21:U23) -> 0 | X24: REINVERSION | AA24: =AA19-AA23 -> #DIV/0! | AB24: =AB19-AB23 -> #DIV/0! | AC24: =AC19-AC23 -> #DIV/0! | AD24: =AD19-AD23 -> #DIV/0! | AE24: =AE19-AE23 -> #DIV/0! | AF24: =AF19-AF23 -> #REF! | AM24: REINVERSION | AP24: =AP19-AP23 -> #DIV/0! | AQ24: =AQ19-AQ23 -> #DIV/0! | AR24: =AR19-AR23 -> #DIV/0! | AS24: =AS19-AS23 -> #DIV/0! | AT24: =AT19-AT23 -> #DIV/0! | AU24: =AU19-AU23 -> #DIV/0! | BC24: REINVERSION | BF24: =BF19-BF23 -> #DIV/0! | BG24: =BG19-BG23 -> #DIV/0! | BH24: =BH19-BH23 -> #DIV/0! | BI24: =BI19-BI23 -> #DIV/0! | BJ24: =BJ19-BJ23 -> #DIV/0! | BK24: =BK19-BK23 -> #REF!
J26: FLUJO DE CAJA LIBRE (FCF) | O26: =+O19-O24 -> 0 | P26: =+P19-P24 -> #REF! | Q26: =+Q19-Q24 -> #REF! | R26: =+R19-R24 -> 0 | S26: =+S19-S24 -> 0 | T26: =T19+T24 -> 0 | U26: =U19+U24 -> 0 | X26: VALOR PRESENTE | AA26: =AA23/((1+$AA$11)^AA6) -> #DIV/0! | AB26: =AB23/((1+$AA$11)^AB6) -> #DIV/0! | AC26: =AC23/((1+$AA$11)^AC6) -> #DIV/0! | AD26: =AD23/((1+$AA$11)^AD6) -> #DIV/0! | AE26: =AE23/((1+$AA$11)^AE6) -> #DIV/0! | AF26: =AF23/((1+$AA$11)^AF6) -> #REF! | AM26: VALOR PRESENTE | AP26: =AP23/((1+$AP$11)^AP6) -> #DIV/0! | AQ26: =AQ23/((1+$AP$11)^AQ6) -> #DIV/0! | AR26: =AR23/((1+$AP$11)^AR6) -> #DIV/0! | AS26: =AS23/((1+$AP$11)^AS6) -> #DIV/0! | AT26: =AT23/((1+$AP$11)^AT6) -> #DIV/0! | AU26: =AU23/((1+$AP$11)^AU6) -> #DIV/0! | BC26: VALOR PRESENTE | BF26: =BF23/((1+$AA$11)^BF6) -> #DIV/0! | BG26: =BG23/((1+$AA$11)^BG6) -> #DIV/0! | BH26: =BH23/((1+$AA$11)^BH6) -> #DIV/0! | BI26: =BI23/((1+$AA$11)^BI6) -> #DIV/0! | BJ26: =BJ23/((1+$AA$11)^BJ6) -> #DIV/0! | BK26: =BK23/((1+$AA$11)^BK6) -> #REF!
J27: REINVERSIÓN | O27: =1-(O26/O15) -> #DIV/0! | P27: =1-(P26/P15) -> #REF! | Q27: =1-(Q26/Q15) -> #REF! | R27: =1-(R26/R15) -> #DIV/0! | S27: =1-(S26/S15) -> #DIV/0! | T27: =1-(T26/T15) -> #DIV/0! | U27: =1-(U26/U15) -> #DIV/0!
J28: FCF % | O28: =1-O27 -> #DIV/0! | P28: =1-P27 -> #REF! | Q28: =1-Q27 -> #REF! | R28: =1-R27 -> #DIV/0! | S28: =1-S27 -> #DIV/0! | T28: =1-T27 -> #DIV/0! | U28: =1-U27 -> #DIV/0! | X28: ∑ VP | AA28: =SUM(AA26:AF26) -> #DIV/0! | AM28: ∑ VP | AP28: =IF(SUM(AP26:AU26)>0,SUM(AP26:AU26),0) -> #DIV/0! | BC28: ∑ VP | BF28: =SUM(BF26:BK26) -> #DIV/0!
J30: MEDIA FCF % | O30: =MEDIAN(T27,U27) -> #DIV/0! | X30: DEUDA | AA30: #REF! | AM30: DEUDA LARGO PLAZO | AP30: =+'1. Datos'!H119 -> 0 | BC30: DEUDA | BF30: #REF!
J32: PROMEDIO FCF % | O32: =+AVERAGE(N28:R28) -> #DIV/0! | X32: VALOR DEL NEGOCIO | AA32: =#REF! -> #REF! | AM32: VALOR DEL NEGOCIO Números redondos | AP32: =ROUND(#REF!+#REF!,-3) -> #REF! | BC32: VALOR DE CAPITAL ACCIONARIO CAP | BF32: =BF28-BF30 -> #DIV/0!
J33: PARA EL FCF%
AA34: =AA26+AA24 -> #DIV/0! | AM34: VALOR NEGOCIO | AP34: =+AP28-AP30 -> #DIV/0!
J35: REINVERSIÓN | O35: =AVERAGE(T28:U28) -> #DIV/0! | BC35: VALOR DEL NEGOCIO | BF35: =BF32 -> #DIV/0!
AM36: VALOR NEG REDONDEADO | AP36: =+ROUND(AP34,-3) -> #DIV/0!
J37: REINVERSIÓN [Damodaran] | O37: =1-'reinvestment us'!D77 -> 0.61280731 | BC37: VALOR DE LA FIRMA | BF37: =BF32+BF30 -> #DIV/0!
AM38: VALOR FIRMA | AP38: =+AP36+AP30 -> #DIV/0!
AW39: Articulo sexto | BC39: NÚMERO DE ACCIONES | BF39: =+AP36 -> #DIV/0!
X40: VALOR DE LA FIRMA | AA40: =#REF!+AA30 -> #REF! | AM40: VALOR TOTAL DE LA ENTIDAD | AP40: =+AP32+AP34 -> #REF!
AC41: #REF! | BC41: VALOR POR ACCIÓN | BF41: =BF35/BF39 -> #DIV/0!
AP48: Valor Empresa | AQ48: =AP36 -> #DIV/0!
AP49: Valor Marca
AN51: VENTAS ANUALES POR EL MULTIPLO DE LAS VENTAS | AP51: %Valor sobre Neg.
AN52: =+AS48*'EV SALES'!E46 -> 0 | AS52: PROPIO | AT52: SECTOR | AU52: FACTOR DE HOMOLOGACION
AP53: Factor Homologacion Operacion + Crecimiento | AR53: 0.8 | AS53: ='1. Datos'!L192 -> #DIV/0! | AT53: ='Expected Growth25'!E48 -> 0.0966 | AU53: 0.8
AP54: Factor Homologacion (Rentabilidad) | AR54: 0.2 | AS54: ='1. Datos'!G183 -> #DIV/0! | AT54: ='operating margin'!E49 -> 0.036514259 | AU54: 0.8
AT55: f.h. | AU55: 0.6
AQ58: EBIT / EV (FCFF ) | AR58: EBIT SECTOR | AS58: EBT HOMOLOGADO
...

Sheet 4.Resumen-Escenario
X2: Tasa Crecimiento ROE/Dividendos
P3: FLUJOS DE EFECTIVO | X3: ='Expected Growth25'!F39 -> 0.0592 | AC3: Modelo a Perpetuidad (Conservador) | AM3: ='Expected Growth25'!E39 -> 0.0742 | BG3: Modelo de Ventaja Competitiva
O4: ='1. Datos'!C2 -> GRUPO OVANDO CONTRUCCIÓN- IMOBILIARIA- TRANSPORTES S.A. de C.V. | AP4: =O4 -> GRUPO OVANDO CONTRUCCIÓN- IMOBILIARIA- TRANSPORTES S.A. de C.V.
M5: HISTÓRICO | X5: G | AA5: PROYECCIÓN | AP5: PROYECCIÓN | AU5: VT | BF5: PROYECCIÓN
M6: 1 | N6: 1 | O6: 1 | P6: 1 | Q6: 1 | R6: =+Q6+1 -> 2 | S6: =+R6+1 -> 3 | T6: =+S6+1 -> 4 | U6: =+T6+1 -> 5 | X6: =AP18 -> #DIV/0! | AA6: 1 | AB6: 2 | AC6: 3 | AD6: 4 | AE6: 5 | AF6: 5 | AM6: 0 | AP6: 1 | AQ6: 2 | AR6: 3 | AS6: 4 | AT6: 5 | AU6: 5 | BF6: 1 | BG6: 2 | BH6: 3 | BI6: 4 | BJ6: 5 | BK6: 5 | BM6: Tasa de Crecimiento para Perpetuidad**
M7: 2014 | N7: 2015 | O7: 2020 | P7: 2020 | Q7: 2021 | R7: =Q7+1 -> 2022 | S7: =R7+1 -> 2023 | T7: =S7+1 -> 2024 | U7: =T7+1 -> 2025 | AP7: 2026 | AQ7: =+AP7+1 -> 2027 | AR7: =+AQ7+1 -> 2028 | AS7: =+AR7+1 -> 2029 | AT7: =+AS7+1 -> 2030 | AU7: =+AT7 -> 2030 | AW7: Tasa de Crecimiento para Perpetuidad** | BF7: =+AA7 -> 0 | BG7: =+AB7 -> 0 | BH7: =+AC7 -> 0 | BI7: =+AD7 -> 0 | BJ7: =+AE7 -> 0 | BK7: =+BJ7 -> 0 | BM7: 0.04
R8: =+R11/Q11-1 -> #DIV/0! | S8: =+S11/R11-1 -> #DIV/0! | T8: =+T11/S11-1 -> #DIV/0! | U8: =+U11/T11-1 -> #DIV/0! | BF8: =+AP8 -> 0 | BG8: =+BF8*(1+BG9) -> 0 | BH8: =+BG8*(1+BH9) -> 0 | BI8: =+BH8*(1+BI9) -> 0 | BJ8: =+BI8*(1+BJ9) -> 0 | BK8: =+BJ8*(1+BK9) -> 0
AW9: 0.0554 | BC9: G crecimiento | BF9: 0.1833 | BG9: =0.1825*(BG6)^(-0.253) -> 0.15314481 | BH9: =0.1825*(BH6)^(-0.253) -> 0.13821373 | BI9: =0.1825*(BI6)^(-0.253) -> 0.12851141 | BJ9: =0.1825*(BJ6)^(-0.253) -> 0.12145725 | BK9: =0.1825*(BK6)^(-0.253) -> 0.12145725 | BM9: **Variación Anual Promedio INPC útlimos 9 años
J11: EBIT | M11: #ERROR! | N11: #REF! | O11: =+'1. Datos'!D15 -> 0 | P11: =+'1. Datos'!E19 -> 0 | Q11: =+'1. Datos'!F19 -> 0 | R11: =+'1. Datos'!G19 -> 0 | S11: =+'1. Datos'!H19 -> 0 | T11: =+'1. Datos'!I19 -> 0 | U11: =+'1. Datos'!K19 -> 0 | X11: WACC | AA11: =+#REF! -> #REF! | AM11: WACC | AP11: =WACC!K26 -> 0.15953943 | AX11: Inflacion | BC11: WACC | BF11: =+AP11 -> 0.15953943 | BM11: Reinversion= | BN11: #REF!
AY12: Se tomo en consideracion la tasa inflacionaria de 3.65% de acuerdo con las perspectivas de inflacion de Banco Mexico
J14: t | M14: 0.3 | N14: 0.3 | O14: 0.3 | P14: 0.3 | Q14: 0.3 | R14: 0.3 | S14: 0.3 | T14: 0.3 | U14: 0.3 | AF14: =+(AE15*(1+X3))/AA11 -> #REF! | AM14: G | AN14: =+'1. Datos'!L192 -> #DIV/0!
J15: NOPAT = EBIT (1-t) | M15: =M11*(1-M14) -> #VALUE! | N15: =N11*(1-N14) -> #REF! | O15: =O11*(1-O14) -> 0 | P15: =P11*(1-P14) -> 0 | Q15: =Q11*(1-Q14) -> 0 | R15: =R11*(1-R14) -> 0 | S15: =S11*(1-S14) -> 0 | T15: =T11*(1-T14) -> 0 | U15: =U11*(1-U14) -> 0 | X15: EBIT (1-t) | AA15: =+AA8*$U$16 -> 0 | AB15: =+AB8*$U$16 -> 0 | AC15: =+AC8*$U$16 -> 0 | AD15: =+AD8*$U$16 -> 0 | AE15: =+AE8*$U$16 -> 0 | AF15: =+(AF8*$U$16)/AA11 -> #REF! | AM15: EBIT (1-t) | AP15: =+U15 -> 0 | AQ15: =+AP19 -> #DIV/0! | AR15: =+AQ19 -> #DIV/0! | AS15: =+AR19 -> #DIV/0! | AT15: =+AS19 -> #DIV/0! | AU15: =+AT19 -> #DIV/0! | BC15: EBIT (1-t) | BF15: =+BF8*$U$16 -> 0 | BG15: =+BG8*$U$16 -> 0 | BH15: =+BH8*$U$16 -> 0 | BI15: =+BI8*$U$16 -> 0 | BJ15: =+BJ8*$U$16 -> 0 | BK15: =((BK8*$U$16)*(1-(X3/BN11))/(BF11-BM7)) -> #REF!
J18: DEPRECIACIÓN | M18: #REF! | N18: 0 | O18: 0 | P18: ='2.Cálculos (2)'!E27 -> 0 | Q18: ='2.Cálculos (2)'!E27 -> 0 | R18: ='2.Cálculos (2)'!F27 -> 0 | S18: ='2.Cálculos (2)'!G27 -> 0 | T18: ='2.Cálculos (2)'!H27 -> 0 | U18: ='2.Cálculos (2)'!I27 -> 0 | AP18: =+AN14 -> #DIV/0! | AQ18: =+AP18 -> #DIV/0! | AR18: =+'Expected Growth25'!F38 -> 0.0618 | AS18: =+AR18 -> 0.0618 | AT18: =+AS18 -> 0.0618 | AU18: 0.0443 | AW18: Valor Terminal = NOPLAT (1+g)
J19: FLUJO BRUTO DE EFECTIVO (FBE) | M19: =M15+M18 -> #VALUE! | N19: =N15+N18 -> #REF! | O19: =O15+O18 -> 0 | P19: =P15+P18 -> 0 | Q19: =Q15+Q18 -> 0 | R19: =R15+R18 -> 0 | S19: =S15+S18 -> 0 | T19: =T15+T18 -> 0 | U19: =U15+U18 -> 0 | X19: EBIT (1-t) | AA19: =AA15*(1+AA18) -> 0 | AB19: =AB15*(1+AB18) -> 0 | AC19: =AC15*(1+AC18) -> 0 | AD19: =AD15*(1+AD18) -> 0 | AE19: =AE15*(1+AE18) -> 0 | AF19: =AF15*(1+AF18) -> #REF! | AM19: FLUJO PROYECTADO = EBIT(1-T)* (1+g) | AP19: =AP15*(1+AP18) -> #DIV/0! | AQ19: =AQ15*(1+AQ18) -> #DIV/0! | AR19: =AR15*(1+AR18) -> #DIV/0! | AS19: =AS15*(1+AS18) -> #DIV/0! | AT19: =AT15*(1+AT18) -> #DIV/0! | AU19: =+(AU15*(1+AU18))/(AP11-AW9) -> #DIV/0! | AX19: WACC -g | BC19: FLUJO PROYECTADO = EBIT(1-T)* (1+g) | BF19: =BF15*(1+BF18) -> 0 | BG19: =BG15*(1+BG18) -> 0 | BH19: =BH15*(1+BH18) -> 0 | BI19: =BI15*(1+BI18) -> 0 | BJ19: =BJ15*(1+BJ18) -> 0 | BK19: =BK15*(1+BK18) -> #REF!
J21: ='2.Cálculos (2)'!B20 -> Δ Capital de Trabajo | O21: =+'2.Cálculos (2)'!C30 -> 0 | P21: =+'2.Cálculos (2)'!D30 -> 6046273 | Q21: =+'2.Cálculos (2)'!E30 -> 0 | R21: =+'2.Cálculos (2)'!F30 -> 0 | S21: =+'2.Cálculos (2)'!G30 -> 0 | T21: =+'2.Cálculos (2)'!H30 -> 0 | U21: =+'2.Cálculos (2)'!I30 -> 0 | X21: VALOR TERMINAL | AA21: =AF19 -> #REF! | AM21: VALOR TERMINAL | AP21: =AU19 -> #DIV/0! | BC21: VALOR TERMINAL | BF21: =BK19 -> #REF!
J22: ='2.Cálculos (2)'!B32 -> Capex | O22: =+'2.Cálculos (2)'!C32 -> 0 | P22: =+'2.Cálculos (2)'!D32 -> 0 | Q22: =+'2.Cálculos (2)'!E32 -> 0 | R22: =+'2.Cálculos (2)'!F32 -> 0 | S22: =+'2.Cálculos (2)'!G32 -> 0 | T22: =+'2.Cálculos (2)'!H32 -> 0 | U22: =+'2.Cálculos (2)'!I32 -> 0
X23: FCF | AA23: =AA19*$O$32 -> #DIV/0! | AB23: =AB19*$O$32 -> #DIV/0! | AC23: =AC19*$O$32 -> #DIV/0! | AD23: =AD19*$O$32 -> #DIV/0! | AE23: =AE19*$O$32 -> #DIV/0! | AF23: =AF19*$O$32 -> #REF! | AM23: FCF | AP23: =AP19-AP24 -> #DIV/0! | AQ23: =AQ19-AQ24 -> #DIV/0! | AR23: =AR19-AR24 -> #DIV/0! | AS23: =AS19-AS24 -> #DIV/0! | AT23: =AT19-AT24 -> #DIV/0! | AU23: =AU19-AU24 -> #DIV/0! | BC23: FCF | BF23: =BF19*$O$32 -> #DIV/0! | BG23: =BG19*$O$32 -> #DIV/0! | BH23: =BH19*$O$32 -> #DIV/0! | BI23: =BI19*$O$32 -> #DIV/0! | BJ23: =BJ19*$O$32 -> #DIV/0! | BK23: =BK19*$O$32 -> #REF!
J24: INVERSION BRUTA | O24: =SUM(O21:O23) -> 0 | P24: =SUM(P21:P23) -> 6046273 | Q24: =SUM(Q21:Q23) -> 0 | R24: =SUM(R21:R23) -> 0 | S24: =SUM(S21:S23) -> 0 | T24: =SUM(T21:T23) -> 0 | U24: =SUM(U21:U23) -> 0 | X24: REINVERSION | AA24: =AA19-AA23 -> #DIV/0! | AB24: =AB19-AB23 -> #DIV/0! | AC24: =AC19-AC23 -> #DIV/0! | AD24: =AD19-AD23 -> #DIV/0! | AE24: =AE19-AE23 -> #DIV/0! | AF24: =AF19-AF23 -> #REF! | AM24: REINVERSION | AP24: =AP19*$O$35 -> #DIV/0! | AQ24: =AQ19*$O$35 -> #DIV/0! | AR24: =AR19*$O$35 -> #DIV/0! | AS24: =AS19*$O$35 -> #DIV/0! | AT24: =AT19*$O$35 -> #DIV/0! | AU24: =AU19*$O$35 -> #DIV/0! | BC24: REINVERSION | BF24: =BF19-BF23 -> #DIV/0! | BG24: =BG19-BG23 -> #DIV/0! | BH24: =BH19-BH23 -> #DIV/0! | BI24: =BI19-BI23 -> #DIV/0! | BJ24: =BJ19-BJ23 -> #DIV/0! | BK24: =BK19-BK23 -> #REF!
J26: FLUJO DE CAJA LIBRE (FCF) | O26: =+O19-O24 -> 0 | P26: =+P19-P24 -> -6046273 | Q26: =+Q19-Q24 -> 0 | R26: =+R19-R24 -> 0 | S26: =+S19-S24 -> 0 | T26: =T19+T24 -> 0 | U26: =U19+U24 -> 0 | X26: VALOR PRESENTE | AA26: =AA23/((1+$AA$11)^AA6) -> #DIV/0! | AB26: =AB23/((1+$AA$11)^AB6) -> #DIV/0! | AC26: =AC23/((1+$AA$11)^AC6) -> #DIV/0! | AD26: =AD23/((1+$AA$11)^AD6) -> #DIV/0! | AE26: =AE23/((1+$AA$11)^AE6) -> #DIV/0! | AF26: =AF23/((1+$AA$11)^AF6) -> #REF! | AM26: VALOR PRESENTE | AP26: =AP23/((1+$AP$11)^AP6) -> #DIV/0! | AQ26: =AQ23/((1+$AP$11)^AQ6) -> #DIV/0! | AR26: =AR23/((1+$AP$11)^AR6) -> #DIV/0! | AS26: =AS23/((1+$AP$11)^AS6) -> #DIV/0! | AT26: =AT23/((1+$AP$11)^AT6) -> #DIV/0! | AU26: =AU23/((1+$AP$11)^AU6) -> #DIV/0! | BC26: VALOR PRESENTE | BF26: =BF23/((1+$AA$11)^BF6) -> #DIV/0! | BG26: =BG23/((1+$AA$11)^BG6) -> #DIV/0! | BH26: =BH23/((1+$AA$11)^BH6) -> #DIV/0! | BI26: =BI23/((1+$AA$11)^BI6) -> #DIV/0! | BJ26: =BJ23/((1+$AA$11)^BJ6) -> #DIV/0! | BK26: =BK23/((1+$AA$11)^BK6) -> #REF!
J27: REINVERSIÓN | O27: =1-(O26/O15) -> #DIV/0! | P27: =1-(P15/P26) -> 1 | Q27: =1-(Q15/Q26) -> #DIV/0! | R27: =1-(R15/R26) -> #DIV/0! | S27: =1-(S15/S26) -> #DIV/0! | T27: =1-(T15/T26) -> #DIV/0! | U27: =1-(U15/U26) -> #DIV/0!
J28: FCF % | O28: =1-O27 -> #DIV/0! | P28: =1-P27 -> 0 | Q28: =1-Q27 -> #DIV/0! | R28: =1-R27 -> #DIV/0! | S28: =1-S27 -> #DIV/0! | T28: =1-T27 -> #DIV/0! | U28: =1-U27 -> #DIV/0! | X28: ∑ VP | AA28: =SUM(AA26:AF26) -> #DIV/0! | AM28: ∑ VP | AP28: =IF(SUM(AP26:AU26)>0,SUM(AP26:AU26),0) -> #DIV/0! | BC28: ∑ VP | BF28: =SUM(BF26:BK26) -> #DIV/0!
J30: MEDIA FCF % | O30: =+AVERAGE(U28,R28,Q28,ABS(T28)) -> #DIV/0! | X30: DEUDA | AA30: #REF! | AM30: DEUDA LARGO PLAZO | AP30: =+'1. Datos'!J119 -> 0 | BC30: DEUDA | BF30: #REF!
J32: PROMEDIO FCF % | O32: =+AVERAGE(N28:R28) -> #DIV/0! | X32: VALOR DEL NEGOCIO | AA32: =#REF! -> #REF! | AM32: VALOR DEL NEGOCIO Números redondos | AP32: =ROUND(#REF!+#REF!,-3) -> #REF! | BC32: VALOR DE CAPITAL ACCIONARIO CAP | BF32: =BF28-BF30 -> #DIV/0!
J33: PARA EL FCF%
AA34: =AA26+AA24 -> #DIV/0! | AM34: VALOR NEGOCIO | AP34: =+AP28-AP30 -> #DIV/0!
J35: REINVERSIÓN | O35: =1-O30 -> #DIV/0! | BC35: VALOR DEL NEGOCIO | BF35: =BF32 -> #DIV/0!
AM36: VALOR NEG REDONDEADO | AP36: =+ROUND(AP34,-3) -> #DIV/0!
J37: REINVERSIÓN [Damodaran] | O37: =+'reinvestment us'!D38 -> 0.84197589 | BC37: VALOR DE LA FIRMA | BF37: =BF32+BF30 -> #DIV/0!
AM38: VALOR FIRMA | AP38: =+AP36+AP30 -> #DIV/0!
AW39: Articulo sexto | BC39: NÚMERO DE ACCIONES | BF39: =+AP36 -> #DIV/0!
X40: VALOR DE LA FIRMA | AA40: =#REF!+AA30 -> #REF! | AM40: VALOR TOTAL DE LA ENTIDAD | AP40: =+AP32+AP34 -> #REF!
AC41: #REF! | BC41: VALOR POR ACCIÓN | BF41: =BF35/BF39 -> #DIV/0!
AR46: =+AP28*30% -> #DIV/0!
AP48: Valor Empresa | AQ48: =AP36 -> #DIV/0!
AP49: Valor Marca
AN51: VENTAS ANUALES POR EL MULTIPLO DE LAS VENTAS | AP51: %Valor sobre Neg.
AN52: =+AS48*'EV SALES'!E46 -> 0 | AS52: PROPIO | AT52: SECTOR | AU52: FACTOR DE HOMOLOGACION
AP53: Factor Homologacion Operacion + Crecimiento | AR53: 0.8 | AS53: =AP18 -> #DIV/0! | AT53: ='Expected Growth25'!E38 -> 0.0927 | AU53: 1
AP54: Factor Homologacion (Rentabilidad) | AR54: 0.2 | AS54: 40%(APROXIM.) | AT54: ='operating margin'!E39 -> 0.060445903 | AU54: 1
AT55: f.h. | AU55: 0.8
...

Sheet Industry Averages (3)
A1: Date updated: | B1: 45662
A2: Created by: | B2: Aswath Damodaran, adamodar@stern.nyu.edu
A3: What is this data? | B3: Enterprise value multiples by sector | F3: Global
A4: Home Page: | B4: http://www.damodaran.com
A5: Data website: | B5: https://pages.stern.nyu.edu/~adamodar/pc/datasets/vebitdaGlobal.xls
A6: Companies in each industry: | B6: https://pages.stern.nyu.edu/~adamodar/pc/datasets/indname.xls
A7: Variable definitions: | B7: https://pages.stern.nyu.edu/~adamodar/New_Home_Page/datafile/variable.htm
C8: Only positive EBITDA firms | G8: All firms
A9: Industry Name | B9: Number of firms | C9: EV/EBITDAR&D | D9: EV/EBITDA | E9: EV/EBIT | F9: EV/EBIT (1-t) | G9: EV/EBITDAR&D | H9: EV/EBITDA | I9: EV/EBIT | J9: EV/EBIT (1-t)
A10: Advertising | B10: 417 | C10: 11.951228 | D10: 12.920253 | E10: 19.470706 | F10: 26.878975 | G10: 14.093445 | H10: 15.385578 | I10: 20.504836 | J10: 28.306573
A11: Aerospace/Defense | B11: 300 | C11: 12.712865 | D11: 17.817018 | E11: 27.4934 | F11: 34.175159 | G11: 15.491837 | H11: 22.485446 | I11: 30.858645 | J11: 38.358264
